Workbook
Name cop: #REF!
Name Slicer_City: #N/A
Name Slicer_Gender: #N/A
Name Slicer_IslateDelivery: #N/A
Name Slicer_Months__Order_Date: #N/A

Sheet data
A1: Customer_ID | B1: First_Name | C1: Last_Name | D1: Age | E1: Gender | F1: City | G1: Email | H1: Address | I1: Order_ID | J1: Order_Date | K1: Order_Time | L1: Product_ID | M1: Price | N1: Quantity | O1: Coupon_Code | P1: Estimated_Days_to_Deliver | Q1: Delivery_Charge | R1: Delivery_Date | S1: Delivery_Time | T1: Days_to_Deliver | U1: Amount | V1: Amount_with_Del_Chrg | W1: Discount_Percent | X1: Discount_Amount | Y1: Final_Amount | Z1: Full_Name | AA1: IslateDelivery | AB1: Month | AC1: Year | AD1: Email_Domain
A2: CID186 | B2: Anne | C2: Oconnell | D2: 37 | E2: Male | F2: Phoenix | G2: anne.oconnell@outlook.com | H2: 2850 Matthew Ford, North Yolandachester, FL 67488 | I2: OID2497 | J2: 45358 | K2: 18:16:33 | L2: PID022 | M2: 308.88 | N2: 5 | O2: FLAT8 | P2: 4 | Q2: 60 | R2: 45361 | S2: 08:51:31 | T2: =R2-J2 -> 3 | U2: =M2*N2 -> 1544.4 | V2: =IF(O2="DEL0",U2,U2+Q2) -> 1604.4 | W2: =IF(O2="FLAT8",8%,IF(O2="FLAT10",10%,IF(O2="FLAT15",15%,IF(O2="FLAT20",20%,0)))) -> 0.08 | X2: =U2*W2 -> 123.552 | Y2: =V2-X2 -> 1480.848 | Z2: =B2&" "&C2 -> Anne Oconnell | AA2: =IF(R2<(J2+P2),"Before Time",IF(R2=(J2+P2),"In Time","Late")) -> Before Time | AB2: =TEXT(J2,"MMM") -> Mar | AC2: =YEAR(J2) -> 2024 | AD2: =RIGHT(G2,LEN(G2)-FIND("@",G2)) -> outlook.com
A3: CID150 | B3: Anthony | C3: Thomas | D3: 53 | E3: Female | F3: Houston | G3: anthony.thomas@rediffmail.com | H3: 931 Christopher Ways Suite 833, North Michelle, IN 53484 | I3: OID7056 | J3: 45378 | K3: 01:46:33 | L3: PID015 | M3: 166.28 | N3: 4 | O3: FLAT8 | P3: 7 | Q3: 66 | R3: 45381 | S3: 18:46:26 | T3: =R3-J3 -> 3 | U3: =M3*N3 -> 665.12 | V3: =IF(O3="DEL0",U3,U3+Q3) -> 731.12 | W3: =IF(O3="FLAT8",8%,IF(O3="FLAT10",10%,IF(O3="FLAT15",15%,IF(O3="FLAT20",20%,0)))) -> 0.08 | X3: =U3*W3 -> 53.2096 | Y3: =V3-X3 -> 677.9104 | Z3: =B3&" "&C3 -> Anthony Thomas | AA3: =IF(R3<(J3+P3),"Before Time",IF(R3=(J3+P3),"In Time","Late")) -> Before Time | AB3: =TEXT(J3,"MMM") -> Mar | AC3: =YEAR(J3) -> 2024 | AD3: =RIGHT(G3,LEN(G3)-FIND("@",G3)) -> rediffmail.com
A4: CID115 | B4: Karl | C4: Gallagher | D4: 60 | E4: Other | F4: Phoenix | G4: karl.gallagher@rediffmail.com | H4: 5016 Snow Mountains Apt. 063, New Seanport, WY 41492 | I4: OID7502 | J4: 45342 | K4: 07:31:36 | L4: PID023 | M4: 202.54 | N4: 1 | O4: FLAT15 | P4: 3 | Q4: 47 | R4: 45344 | S4: 14:29:50 | T4: =R4-J4 -> 2 | U4: =M4*N4 -> 202.54 | V4: =IF(O4="DEL0",U4,U4+Q4) -> 249.54 | W4: =IF(O4="FLAT8",8%,IF(O4="FLAT10",10%,IF(O4="FLAT15",15%,IF(O4="FLAT20",20%,0)))) -> 0.15 | X4: =U4*W4 -> 30.381 | Y4: =V4-X4 -> 219.159 | Z4: =B4&" "&C4 -> Karl Gallagher | AA4: =IF(R4<(J4+P4),"Before Time",IF(R4=(J4+P4),"In Time","Late")) -> Before Time | AB4: =TEXT(J4,"MMM") -> Feb | AC4: =YEAR(J4) -> 2024 | AD4: =RIGHT(G4,LEN(G4)-FIND("@",G4)) -> rediffmail.com
A5: CID115 | B5: Karl | C5: Gallagher | D5: 60 | E5: Other | F5: Phoenix | G5: karl.gallagher@rediffmail.com | H5: 5016 Snow Mountains Apt. 063, New Seanport, WY 41492 | I5: OID7077 | J5: 45426 | K5: 18:29:21 | L5: PID031 | M5: 405 | N5: 5 | O5: DEL0 | P5: 6 | Q5: 47 | R5: 45430 | S5: 07:00:32 | T5: =R5-J5 -> 4 | U5: =M5*N5 -> 2025 | V5: =IF(O5="DEL0",U5,U5+Q5) -> 2025 | W5: =IF(O5="FLAT8",8%,IF(O5="FLAT10",10%,IF(O5="FLAT15",15%,IF(O5="FLAT20",20%,0)))) -> 0 | X5: =U5*W5 -> 0 | Y5: =V5-X5 -> 2025 | Z5: =B5&" "&C5 -> Karl Gallagher | AA5: =IF(R5<(J5+P5),"Before Time",IF(R5=(J5+P5),"In Time","Late")) -> Before Time | AB5: =TEXT(J5,"MMM") -> May | AC5: =YEAR(J5) -> 2024 | AD5: =RIGHT(G5,LEN(G5)-FIND("@",G5)) -> rediffmail.com
A6: CID149 | B6: Angela | C6: Horne | D6: 49 | E6: Other | F6: Phoenix | G6: angela.horne@outlook.com | H6: USNV Mueller, FPO AP 54648 | I6: OID2793 | J6: 45391 | K6: 03:23:21 | L6: PID015 | M6: 166.28 | N6: 1 | O6: FLAT8 | P6: 2 | Q6: 54 | R6: 45395 | S6: 22:10:58 | T6: =R6-J6 -> 4 | U6: =M6*N6 -> 166.28 | V6: =IF(O6="DEL0",U6,U6+Q6) -> 220.28 | W6: =IF(O6="FLAT8",8%,IF(O6="FLAT10",10%,IF(O6="FLAT15",15%,IF(O6="FLAT20",20%,0)))) -> 0.08 | X6: =U6*W6 -> 13.3024 | Y6: =V6-X6 -> 206.9776 | Z6: =B6&" "&C6 -> Angela Horne | AA6: =IF(R6<(J6+P6),"Before Time",IF(R6=(J6+P6),"In Time","Late")) -> Late | AB6: =TEXT(J6,"MMM") -> Apr | AC6: =YEAR(J6) -> 2024 | AD6: =RIGHT(G6,LEN(G6)-FIND("@",G6)) -> outlook.com
A7: CID159 | B7: Christine | C7: West | D7: 53 | E7: Other | F7: New York | G7: christine.west@gmail.com | H7: Unit 1433 Box 0246, DPO AP 94952 | I7: OID1483 | J7: 45543 | K7: 16:55:06 | L7: PID043 | M7: 330.11 | N7: 4 | O7: FLAT15 | P7: 6 | Q7: 39 | R7: 45547 | S7: 11:25:50 | T7: =R7-J7 -> 4 | U7: =M7*N7 -> 1320.44 | V7: =IF(O7="DEL0",U7,U7+Q7) -> 1359.44 | W7: =IF(O7="FLAT8",8%,IF(O7="FLAT10",10%,IF(O7="FLAT15",15%,IF(O7="FLAT20",20%,0)))) -> 0.15 | X7: =U7*W7 -> 198.066 | Y7: =V7-X7 -> 1161.374 | Z7: =B7&" "&C7 -> Christine West | AA7: =IF(R7<(J7+P7),"Before Time",IF(R7=(J7+P7),"In Time","Late")) -> Before Time | AB7: =TEXT(J7,"MMM") -> Sep | AC7: =YEAR(J7) -> 2024 | AD7: =RIGHT(G7,LEN(G7)-FIND("@",G7)) -> gmail.com
A8: CID115 | B8: Karl | C8: Gallagher | D8: 60 | E8: Other | F8: Phoenix | G8: karl.gallagher@rediffmail.com | H8: 5016 Snow Mountains Apt. 063, New Seanport, WY 41492 | I8: OID4105 | J8: 45662 | K8: 09:47:21 | L8: PID022 | M8: 308.88 | N8: 5 | O8: FLAT20 | P8: 5 | Q8: 47 | R8: 45665 | S8: 20:10:50 | T8: =R8-J8 -> 3 | U8: =M8*N8 -> 1544.4 | V8: =IF(O8="DEL0",U8,U8+Q8) -> 1591.4 | W8: =IF(O8="FLAT8",8%,IF(O8="FLAT10",10%,IF(O8="FLAT15",15%,IF(O8="FLAT20",20%,0)))) -> 0.2 | X8: =U8*W8 -> 308.88 | Y8: =V8-X8 -> 1282.52 | Z8: =B8&" "&C8 -> Karl Gallagher | AA8: =IF(R8<(J8+P8),"Before Time",IF(R8=(J8+P8),"In Time","Late")) -> Before Time | AB8: =TEXT(J8,"MMM") -> Jan | AC8: =YEAR(J8) -> 2025 | AD8: =RIGHT(G8,LEN(G8)-FIND("@",G8)) -> rediffmail.com
A9: CID198 | B9: David | C9: Delacruz | D9: 26 | E9: Female | F9: Los Angeles | G9: david.delacruz@rediffmail.com | H9: USNS Ray, FPO AE 20238 | I9: OID4372 | J9: 45459 | K9: 19:27:45 | L9: PID046 | M9: 363.64 | N9: 3 | O9: FLAT10 | P9: 2 | Q9: 70 | R9: 45464 | S9: 12:36:32 | T9: =R9-J9 -> 5 | U9: =M9*N9 -> 1090.92 | V9: =IF(O9="DEL0",U9,U9+Q9) -> 1160.92 | W9: =IF(O9="FLAT8",8%,IF(O9="FLAT10",10%,IF(O9="FLAT15",15%,IF(O9="FLAT20",20%,0)))) -> 0.1 | X9: =U9*W9 -> 109.092 | Y9: =V9-X9 -> 1051.828 | Z9: =B9&" "&C9 -> David Delacruz | AA9: =IF(R9<(J9+P9),"Before Time",IF(R9=(J9+P9),"In Time","Late")) -> Late | AB9: =TEXT(J9,"MMM") -> Jun | AC9: =YEAR(J9) -> 2024 | AD9: =RIGHT(G9,LEN(G9)-FIND("@",G9)) -> rediffmail.com
A10: CID152 | B10: Marcus | C10: Valenzuela | D10: 39 | E10: Male | F10: Phoenix | G10: marcus.valenzuela@yahoo.com | H10: 694 Graham Prairie Apt. 887, Jimenezfurt, MI 33044 | I10: OID3528 | J10: 45040 | K10: 12:07:00 | L10: PID034 | M10: 275.44 | N10: 1 | O10: FLAT8 | P10: 7 | Q10: 63 | R10: 45042 | S10: 23:05:41 | T10: =R10-J10 -> 2 | U10: =M10*N10 -> 275.44 | V10: =IF(O10="DEL0",U10,U10+Q10) -> 338.44 | W10: =IF(O10="FLAT8",8%,IF(O10="FLAT10",10%,IF(O10="FLAT15",15%,IF(O10="FLAT20",20%,0)))) -> 0.08 | X10: =U10*W10 -> 22.0352 | Y10: =V10-X10 -> 316.4048 | Z10: =B10&" "&C10 -> Marcus Valenzuela | AA10: =IF(R10<(J10+P10),"Before Time",IF(R10=(J10+P10),"In Time","Late")) -> Before Time | AB10: =TEXT(J10,"MMM") -> Apr | AC10: =YEAR(J10) -> 2023 | AD10: =RIGHT(G10,LEN(G10)-FIND("@",G10)) -> yahoo.com
A11: CID130 | B11: Debra | C11: Rodriguez | D11: 48 | E11: Other | F11: Houston | G11: debra.rodriguez@rediffmail.com | H11: Unit 5964 Box 0721, DPO AP 01840 | I11: OID9634 | J11: 45282 | K11: 13:46:47 | L11: PID033 | M11: 48.45 | N11: 1 | O11: FLAT15 | P11: 7 | Q11: 59 | R11: 45287 | S11: 19:57:06 | T11: =R11-J11 -> 5 | U11: =M11*N11 -> 48.45 | V11: =IF(O11="DEL0",U11,U11+Q11) -> 107.45 | W11: =IF(O11="FLAT8",8%,IF(O11="FLAT10",10%,IF(O11="FLAT15",15%,IF(O11="FLAT20",20%,0)))) -> 0.15 | X11: =U11*W11 -> 7.2675 | Y11: =V11-X11 -> 100.1825 | Z11: =B11&" "&C11 -> Debra Rodriguez | AA11: =IF(R11<(J11+P11),"Before Time",IF(R11=(J11+P11),"In Time","Late")) -> Before Time | AB11: =TEXT(J11,"MMM") -> Dec | AC11: =YEAR(J11) -> 2023 | AD11: =RIGHT(G11,LEN(G11)-FIND("@",G11)) -> rediffmail.com
A12: CID115 | B12: Karl | C12: Gallagher | D12: 60 | E12: Other | F12: Phoenix | G12: karl.gallagher@rediffmail.com | H12: 5016 Snow Mountains Apt. 063, New Seanport, WY 41492 | I12: OID1905 | J12: 45588 | K12: 17:21:43 | L12: PID046 | M12: 363.64 | N12: 4 | O12: DEL0 | P12: 2 | Q12: 35 | R12: 45590 | S12: 08:00:35 | T12: =R12-J12 -> 2 | U12: =M12*N12 -> 1454.56 | V12: =IF(O12="DEL0",U12,U12+Q12) -> 1454.56 | W12: =IF(O12="FLAT8",8%,IF(O12="FLAT10",10%,IF(O12="FLAT15",15%,IF(O12="FLAT20",20%,0)))) -> 0 | X12: =U12*W12 -> 0 | Y12: =V12-X12 -> 1454.56 | Z12: =B12&" "&C12 -> Karl Gallagher | AA12: =IF(R12<(J12+P12),"Before Time",IF(R12=(J12+P12),"In Time","Late")) -> In Time | AB12: =TEXT(J12,"MMM") -> Oct | AC12: =YEAR(J12) -> 2024 | AD12: =RIGHT(G12,LEN(G12)-FIND("@",G12)) -> rediffmail.com
A13: CID101 | B13: Bobby | C13: Forbes | D13: 20 | E13: Male | F13: Los Angeles | G13: bobby.forbes@gmail.com | H13: 3079 John Parkway Suite 961, Port Kristaview, MT 91019 | I13: OID3136 | J13: 45498 | K13: 15:09:49 | L13: PID007 | M13: 257.06 | N13: 3 | O13: DEL0 | P13: 7 | Q13: 62 | R13: 45499 | S13: 22:54:40 | T13: =R13-J13 -> 1 | U13: =M13*N13 -> 771.18 | V13: =IF(O13="DEL0",U13,U13+Q13) -> 771.18 | W13: =IF(O13="FLAT8",8%,IF(O13="FLAT10",10%,IF(O13="FLAT15",15%,IF(O13="FLAT20",20%,0)))) -> 0 | X13: =U13*W13 -> 0 | Y13: =V13-X13 -> 771.18 | Z13: =B13&" "&C13 -> Bobby Forbes | AA13: =IF(R13<(J13+P13),"Before Time",IF(R13=(J13+P13),"In Time","Late")) -> Before Time | AB13: =TEXT(J13,"MMM") -> Jul | AC13: =YEAR(J13) -> 2024 | AD13: =RIGHT(G13,LEN(G13)-FIND("@",G13)) -> gmail.com
... A501: CID158 | B501: Angela | C501: Evans | D501: 52 | E501: Other | F501: Houston | G501: angela.evans@outlook.com | H501: 16031 David Mountain Suite 431, Susanborough, PA 01910 | I501: OID6847 | J501: 45501 | K501: 17:02:09 | L501: PID010 | M501: 44.5 | N501: 4 | O501: DEL0 | P501: 3 | Q501: 45 | R501: 45504 | S501: 05:55:32 | T501: =R501-J501 -> 3 | U501: =M501*N501 -> 178 | V501: =IF(O501="DEL0",U501,U501+Q501) -> 178 | W501: =IF(O501="FLAT8",8%,IF(O501="FLAT10",10%,IF(O501="FLAT15",15%,IF(O501="FLAT20",20%,0)))) -> 0 | X501: =U501*W501 -> 0 | Y501: =V501-X501 -> 178 | Z501: =B501&" "&C501 -> Angela Evans | AA501: =IF(R501<(J501+P501),"Before Time",IF(R501=(J501+P501),"In Time","Late")) -> In Time | AB501: =TEXT(J501,"MMM") -> Jul | AC501: =YEAR(J501) -> 2024 | AD501: =RIGHT(G501,LEN(G501)-FIND("@",G501)) -> outlook.com

Sheet Project_Questions
B2: 1) Compute the following KPIs
B3: Customer KPIs | G3: Order and Delivery KPIs
B4: a) Find total unique customers | G4: a) Total Orders placed
B5: b) Customer with most orders | G5: b) Average Days to Deliver
B6: c) Customer with highest total order amount | G6: c) Total orders with 0 Delivery Charge
B7: d) Average Customer Age
B10: Product KPIs
B11: a) Find total unique products
B12: b) Most ordered product
B13: c) Product which generated highest revenue
B16: Sales KPI
B17: a) Sum Total Sales generated
B18: b) Sum Total Discount offered
B19: c) Total Sales after Discount
B20: d) Avg Sales(exclduing discount)
B22: Q2) Create a new column, Days to deliver and fill it with number of days it took for delivery
B25: Q3) Create a new Amount by using Price and Quantity
... B50: 10) Extract email from domain and represent its count on a bar chart

Sheet KPISANSWER
A1: Customer KPIs | G1: Order and Delivery KPIs
A2: 1.Total Unique Customer | G2: a) Total Orders placed
A3: =_xlfn.FORMULATEXT(B3) -> =COUNTA(UNIQUE((data!A2:A501))) | B3: =COUNTA(_xlfn.UNIQUE((data!A2:A501))) -> 100 | G3: =_xlfn.FORMULATEXT(H3) -> =COUNTA(data!A2:A501) | H3: =COUNTA(data!A2:A501) -> 500
A5: 2.Customer with more orders | G5: b) Average Days to Deliver
A6: Row Labels | B6: Count of Order_ID | G6: =_xlfn.FORMULATEXT(H6) -> =AVERAGE(data!T2:T501) | H6: =AVERAGE(data!T2:T501) -> 4.002
A7: CID174 | B7: 11
A8: CID162 | B8: 11 | G8: c) Total orders with 0 Delivery Charge
A9: Grand Total | B9: 22 | G9: =_xlfn.FORMULATEXT(H9) -> =COUNTIF(data!O2:O501,"DEL0") | H9: =COUNTIF(data!O2:O501,"DEL0") -> 102
A11: 3. Customer with highest total order amount
A12: Row Labels | B12: Sum of Amount | G12: Product KPIs
A13: CID174 | B13: 14040.5 | G13: a) Find total unique products
A14: Grand Total | B14: 14040.5 | G14: =_xlfn.FORMULATEXT(H14) -> =COUNTA(UNIQUE(data!L2:L501)) | H14: =COUNTA(_xlfn.UNIQUE(data!L2:L501)) -> 50
A16: 4.Average Customer Age | G16: b) Most ordered product
A17: =_xlfn.FORMULATEXT(B17) -> =AVERAGE(data!D2:D501) | B17: =AVERAGE(data!D2:D501) -> 42.124 | G17: Row Labels | H17: Count of Order_ID
G18: PID036 | H18: 17
A19: Sales KPI | G19: Grand Total | H19: 17
A20: a) Sum Total Sales generated
A21: =_xlfn.FORMULATEXT(B21) -> =SUM(data!U2:U501) | B21: =SUM(data!U2:U501) -> 364289.49 | G21: c) Product which generated highest revenue
G22: Row Labels | H22: Sum of Final_Amount
A23: b) Sum Total Discount offered | G23: PID027 | H23: 18975.537
A24: =_xlfn.FORMULATEXT(B24) -> =SUM(data!X2:X501) | B24: =SUM(data!X2:X501) -> 37963.73 | G24: Grand Total | H24: 18975.537
A26: c) Total Sales after Discount
A27: =_xlfn.FORMULATEXT(B27) -> =SUM(data!Y2:Y501) | B27: =SUM(data!Y2:Y501) -> 347189.76
A29: d) Avg Sales(exclduing discount)
A30: =_xlfn.FORMULATEXT(B30) -> =AVERAGE(data!U2:U501) | B30: =AVERAGE(data!U2:U501) -> 728.57898

Sheet VISUAL QUES ANSWER
A1: Visual Analysis - Charts to be generated
A2: 1) Represent top 10 customers with highest Total Sales after Discount on a bar chart | I2: 5) Represent top 5 and bottom 5 products with highest and lowest sales respectively | R2: 8) Find Count of Late, Intime and BeforeTime Deliveries on a Pie chart | W2: 10) Extract email from domain and represent its count on a bar chart
A3: Row Labels | B3: Sum of Final_Amount | I3: Product_ID | J3: Top 5 Sales | K3: Product_ID | L3: Bottom 5 Sales | R3: Row Labels | S3: Count of IslateDelivery
A4: CID174 | B4: 13121.119 | I4: PID027 | J4: 18975.537 | K4: PID038 | L4: 14616.772 | R4: Before Time | S4: 213 | W4: Row Labels | X4: Count of Email_Domain
A5: CID114 | B5: 8428.0983 | I5: PID046 | J5: 16540.572 | K5: PID004 | L5: 15374.888 | R5: In Time | S5: 77 | W5: gmail.com | X5: 112
A6: CID162 | B6: 7999.8487 | I6: PID017 | J6: 15918.949 | K6: PID017 | L6: 15918.949 | R6: Late | S6: 210 | W6: outlook.com | X6: 132
A7: CID165 | B7: 7509.2038 | I7: PID004 | J7: 15374.888 | K7: PID046 | L7: 16540.572 | R7: Grand Total | S7: 500 | W7: rediffmail.com | X7: 118
A8: CID102 | B8: 6873.9278 | I8: PID038 | J8: 14616.772 | K8: PID027 | L8: 18975.537 | W8: yahoo.com | X8: 138
A9: Grand Total | B9: 43932.197 | I9: Grand Total | J9: 81426.718 | K9: Grand Total | L9: 81426.718 | W9: Grand Total | X9: 500
A11: 2) Represent the count of different products ordered and its percentage on a donut chart
A12: Row Labels | B12: Sum of Quantity
A13: PID002 | B13: 51
A14: PID036 | B14: 48
A15: PID046 | B15: 48
A16: PID018 | B16: 44 | I16: 6) Represent Count of all Disocunt Coupon used on a Pie Chart | R16: 9) Represent Year and month wise total sales and total discount on a line chart
A17: PID027 | B17: 42 | I17: Row Labels | J17: Count of Coupon_Code | R17: Row Labels | S17: Sum of Final_Amount | T17: Sum of Discount_Amount
A18: Grand Total | B18: 233 | I18: DEL0 | J18: 102 | R18: 2023
I19: FLAT10 | J19: 100 | R19: Feb | S19: 8961.5454 | T19: 1228.4846
I20: FLAT15 | J20: 83 | R20: Mar | S20: 11944.354 | T20: 1349.8364
A21: 3) Represent city wise total orders on a Funnel Chart | I21: FLAT20 | J21: 104 | R21: Apr | S21: 14874.226 | T21: 2099.6245
A22: Row Labels | B22: Count of Order_ID | I22: FLAT8 | J22: 111 | R22: May | S22: 9597.7084 | T22: 1092.9616
A23: Houston | B23: 80 | D23: Houston | E23: 80 | I23: Grand Total | J23: 500 | R23: Jun | S23: 14390.601 | T23: 1453.1388
A24: San Francisco | B24: 72 | D24: San Francisco | E24: 72 | R24: Jul | S24: 20925.916 | T24: 2492.1742
A25: Los Angeles | B25: 72 | D25: Los Angeles | E25: 72 | R25: Aug | S25: 10232.461 | T25: 1310.9689
A26: Phoenix | B26: 66 | D26: Phoenix | E26: 66 | R26: Sep | S26: 13665.49 | T26: 1845.6801
A27: Dallas | B27: 64 | D27: Dallas | E27: 64 | I27: 7) Represent Month and Gender wise total Sales in a pivot table and also in a clustered bar chart | R27: Oct | S27: 11586.179 | T27: 1209.3606
A28: Chicago | B28: 51 | D28: Chicago | E28: 51 | I28: Sum of Final_Amount | J28: Column Labels | R28: Nov | S28: 13751 | T28: 1099.2896
A29: New York | B29: 51 | D29: New York | E29: 51 | I29: Row Labels | J29: Female | K29: Male | L29: Other | M29: Grand Total | R29: Dec | S29: 11319.313 | T29: 1478.9574
A30: Miami | B30: 44 | D30: Miami | E30: 44 | I30: Jan | J30: 8063.8688 | K30: 6486.0481 | L30: 16803.997 | M30: 31353.914 | R30: 2024
A31: Grand Total | B31: 500 | I31: Feb | J31: 9475.7083 | K31: 8072.472 | L31: 7936.0841 | M31: 25484.264 | R31: Jan | S31: 11702.541 | T31: 1524.0389
I32: Mar | J32: 11343.755 | K32: 7788.398 | L32: 8099.7189 | M32: 27231.871 | R32: Feb | S32: 15007.427 | T32: 1305.033
I33: Apr | J33: 16267.942 | K33: 10276.567 | L33: 12198.697 | M33: 38743.206 | R33: Mar | S33: 15287.518 | T33: 1535.3621
A34: 4) Represent city wise total sales amount after discount | I34: May | J34: 3690.795 | K34: 8384.8598 | L34: 10931.96 | M34: 23007.615 | R34: Apr | S34: 23868.981 | T34: 2503.1091
A35: Row Labels | B35: Sum of Final_Amount | I35: Jun | J35: 10273.452 | K35: 10663.253 | L35: 10819.354 | M35: 31756.059 | R35: May | S35: 13409.906 | T35: 1166.3236
A36: Houston | B36: 60581.07 | I36: Jul | J36: 8533.2344 | K36: 14733.137 | L36: 15693.165 | M36: 38959.536 | R36: Jun | S36: 17365.458 | T36: 1926.8423
A37: San Francisco | B37: 50133.831 | I37: Aug | J37: 10386.377 | K37: 8246.3771 | L37: 9313.5122 | M37: 27946.266 | R37: Jul | S37: 18033.62 | T37: 1417.5396
A38: Los Angeles | B38: 48033.856 | I38: Sep | J38: 5519.7767 | K38: 9926.2537 | L38: 10640.056 | M38: 26086.087 | R38: Aug | S38: 17713.805 | T38: 2241.5051
A39: Dallas | B39: 46488.287 | I39: Oct | J39: 8184.0099 | K39: 9616.4245 | L39: 8559.6702 | M39: 26360.105 | R39: Sep | S39: 12420.597 | T39: 2203.4633
A40: Phoenix | B40: 45879.246 | I40: Nov | J40: 4007.0176 | K40: 5709.56 | L40: 17185.332 | M40: 26901.909 | R40: Oct | S40: 14773.925 | T40: 1822.4348
A41: New York | B41: 40048.267 | I41: Dec | J41: 5244.5116 | K41: 6323.9011 | L41: 14325.334 | M41: 25893.747 | R41: Nov | S41: 13150.909 | T41: 1289.2712
...

Sheet DASHBOARD
E2: TOTAL SALES | I2: AVG DELIVERY | M2: MOST ORDERED | Q2: AVG CUSTOMER AGE | V2: TOTAL DISCOUNT OFFERED
E6: =KPISANSWER!B21 -> 364289.49 | I6: =KPISANSWER!H6 -> 4.002 | M6: =KPISANSWER!H18 -> 17 | Q6: =KPISANSWER!B17 -> 42.124 | V6: =KPISANSWER!B24 -> 37963.73
